[2024-05-05T06:00:19.529+0000] {local_task_job_runner.py:120} INFO - ::group::Pre task execution logs
[2024-05-05T06:00:19.542+0000] {taskinstance.py:2073} INFO - Dependencies all met for dep_context=non-requeueable deps ti=<TaskInstance: sample.feed_to_bigq manual__2024-05-05T05:49:01.286722+00:00 [queued]>
[2024-05-05T06:00:19.549+0000] {taskinstance.py:2073} INFO - Dependencies all met for dep_context=requeueable deps ti=<TaskInstance: sample.feed_to_bigq manual__2024-05-05T05:49:01.286722+00:00 [queued]>
[2024-05-05T06:00:19.549+0000] {taskinstance.py:2303} INFO - Starting attempt 9 of 9
[2024-05-05T06:00:19.568+0000] {taskinstance.py:2327} INFO - Executing <Task(PythonOperator): feed_to_bigq> on 2024-05-05 05:49:01.286722+00:00
[2024-05-05T06:00:19.578+0000] {standard_task_runner.py:90} INFO - Running: ['***', 'tasks', 'run', 'sample', 'feed_to_bigq', 'manual__2024-05-05T05:49:01.286722+00:00', '--job-id', '88', '--raw', '--subdir', 'DAGS_FOLDER/my_dag.py', '--cfg-path', '/tmp/tmpwz_b3t_g']
[2024-05-05T06:00:19.579+0000] {standard_task_runner.py:91} INFO - Job 88: Subtask feed_to_bigq
[2024-05-05T06:00:19.583+0000] {logging_mixin.py:188} WARNING - /home/***/.local/lib/python3.12/site-packages/***/task/task_runner/standard_task_runner.py:61 DeprecationWarning: This process (pid=56943) is multi-threaded, use of fork() may lead to deadlocks in the child.
[2024-05-05T06:00:19.584+0000] {standard_task_runner.py:63} INFO - Started process 56970 to run task
[2024-05-05T06:00:19.620+0000] {task_command.py:426} INFO - Running <TaskInstance: sample.feed_to_bigq manual__2024-05-05T05:49:01.286722+00:00 [running]> on host 5bc5768c5236
[2024-05-05T06:00:19.707+0000] {taskinstance.py:2644} INFO - Exporting env vars: AIRFLOW_CTX_DAG_OWNER='***' AIRFLOW_CTX_DAG_ID='sample' AIRFLOW_CTX_TASK_ID='feed_to_bigq' AIRFLOW_CTX_EXECUTION_DATE='2024-05-05T05:49:01.286722+00:00' AIRFLOW_CTX_TRY_NUMBER='9' AIRFLOW_CTX_DAG_RUN_ID='manual__2024-05-05T05:49:01.286722+00:00'
[2024-05-05T06:00:19.708+0000] {taskinstance.py:430} INFO - ::endgroup::
[2024-05-05T06:00:20.368+0000] {taskinstance.py:441} INFO - ::group::Post task execution logs
[2024-05-05T06:00:20.368+0000] {taskinstance.py:2890} ERROR - Task failed with exception
Traceback (most recent call last):
  File "/home/airflow/.local/lib/python3.12/site-packages/airflow/models/taskinstance.py", line 465, in _execute_task
    result = _execute_callable(context=context, **execute_callable_kwargs)
             ^^^^^^^^^^^^^^^^^^^^^^^^^^^^^^^^^^^^^^^^^^^^^^^^^^^^^^^^^^^^^
  File "/home/airflow/.local/lib/python3.12/site-packages/airflow/models/taskinstance.py", line 432, in _execute_callable
    return execute_callable(context=context, **execute_callable_kwargs)
           ^^^^^^^^^^^^^^^^^^^^^^^^^^^^^^^^^^^^^^^^^^^^^^^^^^^^^^^^^^^^
  File "/home/airflow/.local/lib/python3.12/site-packages/airflow/models/baseoperator.py", line 400, in wrapper
    return func(self, *args, **kwargs)
           ^^^^^^^^^^^^^^^^^^^^^^^^^^^
  File "/home/airflow/.local/lib/python3.12/site-packages/airflow/operators/python.py", line 235, in execute
    return_value = self.execute_callable()
                   ^^^^^^^^^^^^^^^^^^^^^^^
  File "/home/airflow/.local/lib/python3.12/site-packages/airflow/operators/python.py", line 252, in execute_callable
    return self.python_callable(*self.op_args, **self.op_kwargs)
           ^^^^^^^^^^^^^^^^^^^^^^^^^^^^^^^^^^^^^^^^^^^^^^^^^^^^^
  File "/opt/airflow/dags/my_dag.py", line 103, in _feed_to_bigq
    load_job = client.load_table_from_uri(
               ^^^^^^^^^^^^^^^^^^^^^^^^^^^
  File "/home/airflow/.local/lib/python3.12/site-packages/google/cloud/bigquery/client.py", line 2475, in load_table_from_uri
    load_job._begin(retry=retry, timeout=timeout)
  File "/home/airflow/.local/lib/python3.12/site-packages/google/cloud/bigquery/job/base.py", line 740, in _begin
    api_response = client._call_api(
                   ^^^^^^^^^^^^^^^^^
  File "/home/airflow/.local/lib/python3.12/site-packages/google/cloud/bigquery/client.py", line 831, in _call_api
    return call()
           ^^^^^^
  File "/home/airflow/.local/lib/python3.12/site-packages/google/api_core/retry/retry_unary.py", line 293, in retry_wrapped_func
    return retry_target(
           ^^^^^^^^^^^^^
  File "/home/airflow/.local/lib/python3.12/site-packages/google/api_core/retry/retry_unary.py", line 153, in retry_target
    _retry_error_helper(
  File "/home/airflow/.local/lib/python3.12/site-packages/google/api_core/retry/retry_base.py", line 212, in _retry_error_helper
    raise final_exc from source_exc
  File "/home/airflow/.local/lib/python3.12/site-packages/google/api_core/retry/retry_unary.py", line 144, in retry_target
    result = target()
             ^^^^^^^^
  File "/home/airflow/.local/lib/python3.12/site-packages/google/cloud/_http/__init__.py", line 494, in api_request
    raise exceptions.from_http_response(response)
google.api_core.exceptions.NotFound: 404 POST https://bigquery.googleapis.com/bigquery/v2/projects/upbeat-task-421414/jobs?prettyPrint=false: Not found: Dataset upbeat-task-421414:upbeat-task-421414:pm25
[2024-05-05T06:00:20.382+0000] {taskinstance.py:1205} INFO - Marking task as FAILED. dag_id=sample, task_id=feed_to_bigq, execution_date=20240505T054901, start_date=20240505T060019, end_date=20240505T060020
[2024-05-05T06:00:20.405+0000] {standard_task_runner.py:110} ERROR - Failed to execute job 88 for task feed_to_bigq (404 POST https://bigquery.googleapis.com/bigquery/v2/projects/upbeat-task-421414/jobs?prettyPrint=false: Not found: Dataset upbeat-task-421414:upbeat-task-421414:pm25; 56970)
[2024-05-05T06:00:20.446+0000] {local_task_job_runner.py:240} INFO - Task exited with return code 1
[2024-05-05T06:00:20.486+0000] {taskinstance.py:3482} INFO - 0 downstream tasks scheduled from follow-on schedule check
[2024-05-05T06:00:20.504+0000] {local_task_job_runner.py:222} INFO - ::endgroup::
