[2024-05-05T08:16:27.843+0000] {task_context_logger.py:104} ERROR - Executor reports task instance <TaskInstance: sample.get_files manual__2024-05-05T06:09:12.404579+00:00 [queued]> finished (failed) although the task says it's queued. (Info: None) Was the task killed externally?
[2024-05-05T08:17:20.497+0000] {task_context_logger.py:104} ERROR - Executor reports task instance <TaskInstance: sample.get_files manual__2024-05-05T06:09:12.404579+00:00 [queued]> finished (failed) although the task says it's queued. (Info: None) Was the task killed externally?
