[2024-05-04T11:42:04.133+0000] {local_task_job_runner.py:120} INFO - ::group::Pre task execution logs
[2024-05-04T11:42:04.161+0000] {taskinstance.py:2073} INFO - Dependencies all met for dep_context=non-requeueable deps ti=<TaskInstance: sample.get_files manual__2024-05-04T11:42:00.359037+00:00 [queued]>
[2024-05-04T11:42:04.178+0000] {taskinstance.py:2073} INFO - Dependencies all met for dep_context=requeueable deps ti=<TaskInstance: sample.get_files manual__2024-05-04T11:42:00.359037+00:00 [queued]>
[2024-05-04T11:42:04.179+0000] {taskinstance.py:2303} INFO - Starting attempt 1 of 1
[2024-05-04T11:42:04.203+0000] {taskinstance.py:2327} INFO - Executing <Task(PythonOperator): get_files> on 2024-05-04 11:42:00.359037+00:00
[2024-05-04T11:42:04.232+0000] {logging_mixin.py:188} WARNING - /home/***/.local/lib/python3.12/site-packages/***/task/task_runner/standard_task_runner.py:61 DeprecationWarning: This process (pid=59578) is multi-threaded, use of fork() may lead to deadlocks in the child.
[2024-05-04T11:42:04.242+0000] {standard_task_runner.py:63} INFO - Started process 59617 to run task
[2024-05-04T11:42:04.239+0000] {standard_task_runner.py:90} INFO - Running: ['***', 'tasks', 'run', 'sample', 'get_files', 'manual__2024-05-04T11:42:00.359037+00:00', '--job-id', '22', '--raw', '--subdir', 'DAGS_FOLDER/my_dag.py', '--cfg-path', '/tmp/tmpnrn36ki3']
[2024-05-04T11:42:04.244+0000] {standard_task_runner.py:91} INFO - Job 22: Subtask get_files
[2024-05-04T11:42:04.331+0000] {task_command.py:426} INFO - Running <TaskInstance: sample.get_files manual__2024-05-04T11:42:00.359037+00:00 [running]> on host 5bc5768c5236
[2024-05-04T11:42:04.678+0000] {taskinstance.py:2644} INFO - Exporting env vars: AIRFLOW_CTX_DAG_OWNER='***' AIRFLOW_CTX_DAG_ID='sample' AIRFLOW_CTX_TASK_ID='get_files' AIRFLOW_CTX_EXECUTION_DATE='2024-05-04T11:42:00.359037+00:00' AIRFLOW_CTX_TRY_NUMBER='1' AIRFLOW_CTX_DAG_RUN_ID='manual__2024-05-04T11:42:00.359037+00:00'
[2024-05-04T11:42:04.679+0000] {taskinstance.py:430} INFO - ::endgroup::
[2024-05-04T11:42:04.952+0000] {logging_mixin.py:188} WARNING - /home/***/.local/lib/python3.12/site-packages/urllib3/connectionpool.py:1061 InsecureRequestWarning: Unverified HTTPS request is being made to host 'opendata.onde.go.th'. Adding certificate verification is strongly advised. See: https://urllib3.readthedocs.io/en/1.26.x/advanced-usage.html#ssl-warnings
[2024-05-04T11:42:08.426+0000] {taskinstance.py:441} INFO - ::group::Post task execution logs
[2024-05-04T11:42:08.427+0000] {taskinstance.py:2890} ERROR - Task failed with exception
Traceback (most recent call last):
  File "/home/airflow/.local/lib/python3.12/site-packages/airflow/models/taskinstance.py", line 465, in _execute_task
    result = _execute_callable(context=context, **execute_callable_kwargs)
             ^^^^^^^^^^^^^^^^^^^^^^^^^^^^^^^^^^^^^^^^^^^^^^^^^^^^^^^^^^^^^
  File "/home/airflow/.local/lib/python3.12/site-packages/airflow/models/taskinstance.py", line 432, in _execute_callable
    return execute_callable(context=context, **execute_callable_kwargs)
           ^^^^^^^^^^^^^^^^^^^^^^^^^^^^^^^^^^^^^^^^^^^^^^^^^^^^^^^^^^^^
  File "/home/airflow/.local/lib/python3.12/site-packages/airflow/models/baseoperator.py", line 400, in wrapper
    return func(self, *args, **kwargs)
           ^^^^^^^^^^^^^^^^^^^^^^^^^^^
  File "/home/airflow/.local/lib/python3.12/site-packages/airflow/operators/python.py", line 235, in execute
    return_value = self.execute_callable()
                   ^^^^^^^^^^^^^^^^^^^^^^^
  File "/home/airflow/.local/lib/python3.12/site-packages/airflow/operators/python.py", line 252, in execute_callable
    return self.python_callable(*self.op_args, **self.op_kwargs)
           ^^^^^^^^^^^^^^^^^^^^^^^^^^^^^^^^^^^^^^^^^^^^^^^^^^^^^
  File "/opt/airflow/dags/my_dag.py", line 34, in _get_files
    if (name != "data_dictionary.csv") & (name not in exit_file_name):
                                                      ^^^^^^^^^^^^^^
NameError: name 'exit_file_name' is not defined
[2024-05-04T11:42:08.452+0000] {taskinstance.py:1205} INFO - Marking task as FAILED. dag_id=sample, task_id=get_files, execution_date=20240504T114200, start_date=20240504T114204, end_date=20240504T114208
[2024-05-04T11:42:08.468+0000] {standard_task_runner.py:110} ERROR - Failed to execute job 22 for task get_files (name 'exit_file_name' is not defined; 59617)
[2024-05-04T11:42:08.520+0000] {local_task_job_runner.py:240} INFO - Task exited with return code 1
[2024-05-04T11:42:08.542+0000] {taskinstance.py:3482} INFO - 0 downstream tasks scheduled from follow-on schedule check
[2024-05-04T11:42:08.687+0000] {local_task_job_runner.py:222} INFO - ::endgroup::
