[2024-05-05T10:16:46.805+0000] {local_task_job_runner.py:120} INFO - ::group::Pre task execution logs
[2024-05-05T10:16:46.817+0000] {taskinstance.py:2073} INFO - Dependencies all met for dep_context=non-requeueable deps ti=<TaskInstance: sample.transform_to_db manual__2024-05-05T10:06:43.455582+00:00 [queued]>
[2024-05-05T10:16:46.824+0000] {taskinstance.py:2073} INFO - Dependencies all met for dep_context=requeueable deps ti=<TaskInstance: sample.transform_to_db manual__2024-05-05T10:06:43.455582+00:00 [queued]>
[2024-05-05T10:16:46.824+0000] {taskinstance.py:2303} INFO - Starting attempt 7 of 7
[2024-05-05T10:16:46.839+0000] {taskinstance.py:2327} INFO - Executing <Task(PythonOperator): transform_to_db> on 2024-05-05 10:06:43.455582+00:00
[2024-05-05T10:16:46.848+0000] {standard_task_runner.py:90} INFO - Running: ['***', 'tasks', 'run', 'sample', 'transform_to_db', 'manual__2024-05-05T10:06:43.455582+00:00', '--job-id', '202', '--raw', '--subdir', 'DAGS_FOLDER/my_dag.py', '--cfg-path', '/tmp/tmph2qvowe9']
[2024-05-05T10:16:46.849+0000] {logging_mixin.py:188} WARNING - /home/***/.local/lib/python3.12/site-packages/***/task/task_runner/standard_task_runner.py:61 DeprecationWarning: This process (pid=85079) is multi-threaded, use of fork() may lead to deadlocks in the child.
[2024-05-05T10:16:46.850+0000] {standard_task_runner.py:91} INFO - Job 202: Subtask transform_to_db
[2024-05-05T10:16:46.850+0000] {standard_task_runner.py:63} INFO - Started process 85096 to run task
[2024-05-05T10:16:46.892+0000] {task_command.py:426} INFO - Running <TaskInstance: sample.transform_to_db manual__2024-05-05T10:06:43.455582+00:00 [running]> on host 5bc5768c5236
[2024-05-05T10:16:46.976+0000] {taskinstance.py:2644} INFO - Exporting env vars: AIRFLOW_CTX_DAG_OWNER='***' AIRFLOW_CTX_DAG_ID='sample' AIRFLOW_CTX_TASK_ID='transform_to_db' AIRFLOW_CTX_EXECUTION_DATE='2024-05-05T10:06:43.455582+00:00' AIRFLOW_CTX_TRY_NUMBER='7' AIRFLOW_CTX_DAG_RUN_ID='manual__2024-05-05T10:06:43.455582+00:00'
[2024-05-05T10:16:46.977+0000] {taskinstance.py:430} INFO - ::endgroup::
[2024-05-05T10:16:47.553+0000] {logging_mixin.py:188} WARNING - /opt/***/dags/my_dag.py:128 SettingWithCopyWarning: 
A value is trying to be set on a copy of a slice from a DataFrame

See the caveats in the documentation: https://pandas.pydata.org/pandas-docs/stable/user_guide/indexing.html#returning-a-view-versus-a-copy
[2024-05-05T10:16:47.568+0000] {taskinstance.py:441} INFO - ::group::Post task execution logs
[2024-05-05T10:16:47.569+0000] {taskinstance.py:2890} ERROR - Task failed with exception
Traceback (most recent call last):
  File "/home/airflow/.local/lib/python3.12/site-packages/airflow/models/taskinstance.py", line 465, in _execute_task
    result = _execute_callable(context=context, **execute_callable_kwargs)
             ^^^^^^^^^^^^^^^^^^^^^^^^^^^^^^^^^^^^^^^^^^^^^^^^^^^^^^^^^^^^^
  File "/home/airflow/.local/lib/python3.12/site-packages/airflow/models/taskinstance.py", line 432, in _execute_callable
    return execute_callable(context=context, **execute_callable_kwargs)
           ^^^^^^^^^^^^^^^^^^^^^^^^^^^^^^^^^^^^^^^^^^^^^^^^^^^^^^^^^^^^
  File "/home/airflow/.local/lib/python3.12/site-packages/airflow/models/baseoperator.py", line 400, in wrapper
    return func(self, *args, **kwargs)
           ^^^^^^^^^^^^^^^^^^^^^^^^^^^
  File "/home/airflow/.local/lib/python3.12/site-packages/airflow/operators/python.py", line 235, in execute
    return_value = self.execute_callable()
                   ^^^^^^^^^^^^^^^^^^^^^^^
  File "/home/airflow/.local/lib/python3.12/site-packages/airflow/operators/python.py", line 252, in execute_callable
    return self.python_callable(*self.op_args, **self.op_kwargs)
           ^^^^^^^^^^^^^^^^^^^^^^^^^^^^^^^^^^^^^^^^^^^^^^^^^^^^^
  File "/opt/airflow/dags/my_dag.py", line 136, in _transform_to_db
    table_station = dataset_ref.table('station')
                    ^^^^^^^^^^^
NameError: name 'dataset_ref' is not defined
[2024-05-05T10:16:47.627+0000] {taskinstance.py:1205} INFO - Marking task as FAILED. dag_id=sample, task_id=transform_to_db, execution_date=20240505T100643, start_date=20240505T101646, end_date=20240505T101647
[2024-05-05T10:16:47.657+0000] {standard_task_runner.py:110} ERROR - Failed to execute job 202 for task transform_to_db (name 'dataset_ref' is not defined; 85096)
[2024-05-05T10:16:47.708+0000] {local_task_job_runner.py:240} INFO - Task exited with return code 1
[2024-05-05T10:16:47.738+0000] {taskinstance.py:3482} INFO - 0 downstream tasks scheduled from follow-on schedule check
[2024-05-05T10:16:47.747+0000] {local_task_job_runner.py:222} INFO - ::endgroup::
