[2024-05-05T10:07:18.733+0000] {local_task_job_runner.py:120} INFO - ::group::Pre task execution logs
[2024-05-05T10:07:18.746+0000] {taskinstance.py:2073} INFO - Dependencies all met for dep_context=non-requeueable deps ti=<TaskInstance: sample.transform_to_db manual__2024-05-05T10:06:43.455582+00:00 [queued]>
[2024-05-05T10:07:18.753+0000] {taskinstance.py:2073} INFO - Dependencies all met for dep_context=requeueable deps ti=<TaskInstance: sample.transform_to_db manual__2024-05-05T10:06:43.455582+00:00 [queued]>
[2024-05-05T10:07:18.753+0000] {taskinstance.py:2303} INFO - Starting attempt 1 of 1
[2024-05-05T10:07:18.769+0000] {taskinstance.py:2327} INFO - Executing <Task(PythonOperator): transform_to_db> on 2024-05-05 10:06:43.455582+00:00
[2024-05-05T10:07:18.779+0000] {logging_mixin.py:188} WARNING - /home/***/.local/lib/python3.12/site-packages/***/task/task_runner/standard_task_runner.py:61 DeprecationWarning: This process (pid=79845) is multi-threaded, use of fork() may lead to deadlocks in the child.
[2024-05-05T10:07:18.779+0000] {standard_task_runner.py:90} INFO - Running: ['***', 'tasks', 'run', 'sample', 'transform_to_db', 'manual__2024-05-05T10:06:43.455582+00:00', '--job-id', '196', '--raw', '--subdir', 'DAGS_FOLDER/my_dag.py', '--cfg-path', '/tmp/tmppx2sucl5']
[2024-05-05T10:07:18.780+0000] {standard_task_runner.py:63} INFO - Started process 79847 to run task
[2024-05-05T10:07:18.780+0000] {standard_task_runner.py:91} INFO - Job 196: Subtask transform_to_db
[2024-05-05T10:07:18.820+0000] {task_command.py:426} INFO - Running <TaskInstance: sample.transform_to_db manual__2024-05-05T10:06:43.455582+00:00 [running]> on host 5bc5768c5236
[2024-05-05T10:07:18.897+0000] {taskinstance.py:2644} INFO - Exporting env vars: AIRFLOW_CTX_DAG_OWNER='***' AIRFLOW_CTX_DAG_ID='sample' AIRFLOW_CTX_TASK_ID='transform_to_db' AIRFLOW_CTX_EXECUTION_DATE='2024-05-05T10:06:43.455582+00:00' AIRFLOW_CTX_TRY_NUMBER='1' AIRFLOW_CTX_DAG_RUN_ID='manual__2024-05-05T10:06:43.455582+00:00'
[2024-05-05T10:07:18.899+0000] {taskinstance.py:430} INFO - ::endgroup::
[2024-05-05T10:07:19.279+0000] {logging_mixin.py:188} WARNING - /opt/***/dags/my_dag.py:128 SettingWithCopyWarning: 
A value is trying to be set on a copy of a slice from a DataFrame

See the caveats in the documentation: https://pandas.pydata.org/pandas-docs/stable/user_guide/indexing.html#returning-a-view-versus-a-copy
[2024-05-05T10:07:19.280+0000] {taskinstance.py:441} INFO - ::group::Post task execution logs
[2024-05-05T10:07:19.280+0000] {taskinstance.py:2890} ERROR - Task failed with exception
Traceback (most recent call last):
  File "/home/airflow/.local/lib/python3.12/site-packages/airflow/models/taskinstance.py", line 465, in _execute_task
    result = _execute_callable(context=context, **execute_callable_kwargs)
             ^^^^^^^^^^^^^^^^^^^^^^^^^^^^^^^^^^^^^^^^^^^^^^^^^^^^^^^^^^^^^
  File "/home/airflow/.local/lib/python3.12/site-packages/airflow/models/taskinstance.py", line 432, in _execute_callable
    return execute_callable(context=context, **execute_callable_kwargs)
           ^^^^^^^^^^^^^^^^^^^^^^^^^^^^^^^^^^^^^^^^^^^^^^^^^^^^^^^^^^^^
  File "/home/airflow/.local/lib/python3.12/site-packages/airflow/models/baseoperator.py", line 400, in wrapper
    return func(self, *args, **kwargs)
           ^^^^^^^^^^^^^^^^^^^^^^^^^^^
  File "/home/airflow/.local/lib/python3.12/site-packages/airflow/operators/python.py", line 235, in execute
    return_value = self.execute_callable()
                   ^^^^^^^^^^^^^^^^^^^^^^^
  File "/home/airflow/.local/lib/python3.12/site-packages/airflow/operators/python.py", line 252, in execute_callable
    return self.python_callable(*self.op_args, **self.op_kwargs)
           ^^^^^^^^^^^^^^^^^^^^^^^^^^^^^^^^^^^^^^^^^^^^^^^^^^^^^
  File "/opt/airflow/dags/my_dag.py", line 129, in _transform_to_db
    df['province_id'] = df['Province'].apply(replace_province_name)
                        ^^^^^^^^^^^^^^^^^^^^^^^^^^^^^^^^^^^^^^^^^^^
  File "/home/airflow/.local/lib/python3.12/site-packages/pandas/core/series.py", line 4764, in apply
    ).apply()
      ^^^^^^^
  File "/home/airflow/.local/lib/python3.12/site-packages/pandas/core/apply.py", line 1209, in apply
    return self.apply_standard()
           ^^^^^^^^^^^^^^^^^^^^^
  File "/home/airflow/.local/lib/python3.12/site-packages/pandas/core/apply.py", line 1289, in apply_standard
    mapped = obj._map_values(
             ^^^^^^^^^^^^^^^^
  File "/home/airflow/.local/lib/python3.12/site-packages/pandas/core/base.py", line 921, in _map_values
    return algorithms.map_array(arr, mapper, na_action=na_action, convert=convert)
           ^^^^^^^^^^^^^^^^^^^^^^^^^^^^^^^^^^^^^^^^^^^^^^^^^^^^^^^^^^^^^^^^^^^^^^^
  File "/home/airflow/.local/lib/python3.12/site-packages/pandas/core/algorithms.py", line 1814, in map_array
    return lib.map_infer(values, mapper, convert=convert)
           ^^^^^^^^^^^^^^^^^^^^^^^^^^^^^^^^^^^^^^^^^^^^^^
  File "lib.pyx", line 2926, in pandas._libs.lib.map_infer
  File "/opt/airflow/dags/my_dag.py", line 111, in replace_province_name
    return province_name.index(x)
           ^^^^^^^^^^^^^
NameError: name 'province_name' is not defined
[2024-05-05T10:07:19.315+0000] {taskinstance.py:1205} INFO - Marking task as FAILED. dag_id=sample, task_id=transform_to_db, execution_date=20240505T100643, start_date=20240505T100718, end_date=20240505T100719
[2024-05-05T10:07:19.330+0000] {standard_task_runner.py:110} ERROR - Failed to execute job 196 for task transform_to_db (name 'province_name' is not defined; 79847)
[2024-05-05T10:07:19.357+0000] {local_task_job_runner.py:240} INFO - Task exited with return code 1
[2024-05-05T10:07:19.376+0000] {taskinstance.py:3482} INFO - 0 downstream tasks scheduled from follow-on schedule check
[2024-05-05T10:07:19.384+0000] {local_task_job_runner.py:222} INFO - ::endgroup::
