[2024-05-05T10:12:26.864+0000] {local_task_job_runner.py:120} INFO - ::group::Pre task execution logs
[2024-05-05T10:12:26.877+0000] {taskinstance.py:2073} INFO - Dependencies all met for dep_context=non-requeueable deps ti=<TaskInstance: sample.transform_to_db manual__2024-05-05T10:06:43.455582+00:00 [queued]>
[2024-05-05T10:12:26.883+0000] {taskinstance.py:2073} INFO - Dependencies all met for dep_context=requeueable deps ti=<TaskInstance: sample.transform_to_db manual__2024-05-05T10:06:43.455582+00:00 [queued]>
[2024-05-05T10:12:26.883+0000] {taskinstance.py:2303} INFO - Starting attempt 4 of 4
[2024-05-05T10:12:26.899+0000] {taskinstance.py:2327} INFO - Executing <Task(PythonOperator): transform_to_db> on 2024-05-05 10:06:43.455582+00:00
[2024-05-05T10:12:26.909+0000] {logging_mixin.py:188} WARNING - /home/***/.local/lib/python3.12/site-packages/***/task/task_runner/standard_task_runner.py:61 DeprecationWarning: This process (pid=82631) is multi-threaded, use of fork() may lead to deadlocks in the child.
[2024-05-05T10:12:26.909+0000] {standard_task_runner.py:90} INFO - Running: ['***', 'tasks', 'run', 'sample', 'transform_to_db', 'manual__2024-05-05T10:06:43.455582+00:00', '--job-id', '199', '--raw', '--subdir', 'DAGS_FOLDER/my_dag.py', '--cfg-path', '/tmp/tmpevq4h3ua']
[2024-05-05T10:12:26.910+0000] {standard_task_runner.py:63} INFO - Started process 82633 to run task
[2024-05-05T10:12:26.910+0000] {standard_task_runner.py:91} INFO - Job 199: Subtask transform_to_db
[2024-05-05T10:12:26.951+0000] {task_command.py:426} INFO - Running <TaskInstance: sample.transform_to_db manual__2024-05-05T10:06:43.455582+00:00 [running]> on host 5bc5768c5236
[2024-05-05T10:12:27.029+0000] {taskinstance.py:2644} INFO - Exporting env vars: AIRFLOW_CTX_DAG_OWNER='***' AIRFLOW_CTX_DAG_ID='sample' AIRFLOW_CTX_TASK_ID='transform_to_db' AIRFLOW_CTX_EXECUTION_DATE='2024-05-05T10:06:43.455582+00:00' AIRFLOW_CTX_TRY_NUMBER='4' AIRFLOW_CTX_DAG_RUN_ID='manual__2024-05-05T10:06:43.455582+00:00'
[2024-05-05T10:12:27.030+0000] {taskinstance.py:430} INFO - ::endgroup::
[2024-05-05T10:12:27.591+0000] {logging_mixin.py:188} WARNING - /opt/***/dags/my_dag.py:128 SettingWithCopyWarning: 
A value is trying to be set on a copy of a slice from a DataFrame

See the caveats in the documentation: https://pandas.pydata.org/pandas-docs/stable/user_guide/indexing.html#returning-a-view-versus-a-copy
[2024-05-05T10:12:27.622+0000] {taskinstance.py:441} INFO - ::group::Post task execution logs
[2024-05-05T10:12:27.622+0000] {taskinstance.py:2890} ERROR - Task failed with exception
Traceback (most recent call last):
  File "/home/airflow/.local/lib/python3.12/site-packages/airflow/models/taskinstance.py", line 465, in _execute_task
    result = _execute_callable(context=context, **execute_callable_kwargs)
             ^^^^^^^^^^^^^^^^^^^^^^^^^^^^^^^^^^^^^^^^^^^^^^^^^^^^^^^^^^^^^
  File "/home/airflow/.local/lib/python3.12/site-packages/airflow/models/taskinstance.py", line 432, in _execute_callable
    return execute_callable(context=context, **execute_callable_kwargs)
           ^^^^^^^^^^^^^^^^^^^^^^^^^^^^^^^^^^^^^^^^^^^^^^^^^^^^^^^^^^^^
  File "/home/airflow/.local/lib/python3.12/site-packages/airflow/models/baseoperator.py", line 400, in wrapper
    return func(self, *args, **kwargs)
           ^^^^^^^^^^^^^^^^^^^^^^^^^^^
  File "/home/airflow/.local/lib/python3.12/site-packages/airflow/operators/python.py", line 235, in execute
    return_value = self.execute_callable()
                   ^^^^^^^^^^^^^^^^^^^^^^^
  File "/home/airflow/.local/lib/python3.12/site-packages/airflow/operators/python.py", line 252, in execute_callable
    return self.python_callable(*self.op_args, **self.op_kwargs)
           ^^^^^^^^^^^^^^^^^^^^^^^^^^^^^^^^^^^^^^^^^^^^^^^^^^^^^
  File "/opt/airflow/dags/my_dag.py", line 129, in _transform_to_db
    df['province_id'] = df['Province'].apply(lambda x : province_name.index(x)).astyp(int)
                        ^^^^^^^^^^^^^^^^^^^^^^^^^^^^^^^^^^^^^^^^^^^^^^^^^^^^^^^^^^^^^
  File "/home/airflow/.local/lib/python3.12/site-packages/pandas/core/generic.py", line 6204, in __getattr__
    return object.__getattribute__(self, name)
           ^^^^^^^^^^^^^^^^^^^^^^^^^^^^^^^^^^^
AttributeError: 'Series' object has no attribute 'astyp'. Did you mean: 'astype'?
[2024-05-05T10:12:27.672+0000] {taskinstance.py:1205} INFO - Marking task as FAILED. dag_id=sample, task_id=transform_to_db, execution_date=20240505T100643, start_date=20240505T101226, end_date=20240505T101227
[2024-05-05T10:12:27.718+0000] {standard_task_runner.py:110} ERROR - Failed to execute job 199 for task transform_to_db ('Series' object has no attribute 'astyp'; 82633)
[2024-05-05T10:12:27.784+0000] {local_task_job_runner.py:240} INFO - Task exited with return code 1
[2024-05-05T10:12:27.805+0000] {taskinstance.py:3482} INFO - 0 downstream tasks scheduled from follow-on schedule check
[2024-05-05T10:12:27.813+0000] {local_task_job_runner.py:222} INFO - ::endgroup::
